Workbook

Sheet Start Here
A1: Script Store Operations Analysis
A2: Synthetic public workbook. No original pivot caches were copied.
A3: Start with Dashboard, then inspect Raw Data, Script_List, Assumptions and Checks.
A4: Raw Data: one operated session per row; Script_List: one fictional script per row.
A5: Five native PivotTables are rebuilt from synthetic caches on Pivot_Analysis.
A6: After changing inputs: allow Excel calculation, then Data > Refresh All for PivotTables.
A7: Charts use formula helpers; top-20 and scatter membership reflect this 416-session snapshot.
A8: If adding new scripts, extend helper ranges and recalculate median cutoffs before reviewing segments.
A9: Standard DM Wage is a supplied total wage input; tips are outside store economics.
A10: No claim of actual business impact. See GitHub documentation for decisions and limits.
A11: Validation: independent numerical controls checked; native Excel refresh still requires a user check.

Sheet Dashboard
A1: Script Store Performance Dashboard
A2: Synthetic data | Sep 2025–Oct 8, 2026 | Estimated contribution is not net profit
A4: Sessions | D4: Estimated Revenue | G4: Estimated Contribution | J4: Scripts Opened
A5: =COUNTA(RawData[Session ID]) -> 416 | D5: =SUM(RawData[Estimated Gross Revenue]) -> 280352 | G5: =SUM(RawData[Estimated Contribution]) -> 195440 | J5: =COUNTIF(Script_List[Observed Session Count],">0") -> 136
P8: Month | Q8: Sessions
P9: 45901 | Q9: =COUNTIF(RawData[Month Start],P9) -> 31
P10: 45931 | Q10: =COUNTIF(RawData[Month Start],P10) -> 32
P11: 45962 | Q11: =COUNTIF(RawData[Month Start],P11) -> 31
P12: 45992 | Q12: =COUNTIF(RawData[Month Start],P12) -> 32
P13: 46023 | Q13: =COUNTIF(RawData[Month Start],P13) -> 32
P14: 46054 | Q14: =COUNTIF(RawData[Month Start],P14) -> 29
P15: 46082 | Q15: =COUNTIF(RawData[Month Start],P15) -> 32
P16: 46113 | Q16: =COUNTIF(RawData[Month Start],P16) -> 31
P17: 46143 | Q17: =COUNTIF(RawData[Month Start],P17) -> 32
P18: 46174 | Q18: =COUNTIF(RawData[Month Start],P18) -> 31
P19: 46204 | Q19: =COUNTIF(RawData[Month Start],P19) -> 32
P20: 46235 | Q20: =COUNTIF(RawData[Month Start],P20) -> 32
... P22: 46296 | Q22: =COUNTIF(RawData[Month Start],P22) -> 8
P25: Edition | Q25: Contribution / Session | R25: Sessions
P26: 城限 | Q26: =AVERAGEIF(RawData[Script Edition],P26,RawData[Estimated Contribution]) -> 505.5 | R26: =COUNTIF(RawData[Script Edition],P26) -> 144
P27: 独家 | Q27: =AVERAGEIF(RawData[Script Edition],P27,RawData[Estimated Contribution]) -> 527.85714 | R27: =COUNTIF(RawData[Script Edition],P27) -> 56
P28: 盒装 | Q28: =AVERAGEIF(RawData[Script Edition],P28,RawData[Estimated Contribution]) -> 430.96296 | R28: =COUNTIF(RawData[Script Edition],P28) -> 216
P31: Opened Script | Q31: Sessions | R31: Contribution / Session | T31: Frequency cutoff X | U31: Cutoff Y | V31: Contribution cutoff X | W31: Cutoff Y
P32: SYN-002 | Q32: =INDEX(Script_List!$R$2:$R$161,MATCH(P32,Script_List!$A$2:$A$161,0)) -> 1 | R32: =INDEX(Script_List!$X$2:$X$161,MATCH(P32,Script_List!$A$2:$A$161,0)) -> 332 | T32: =Assumptions!B3 -> 2 | U32: =0 -> 0 | V32: =0 -> 0 | W32: =Assumptions!B4 -> 490
P33: SYN-003 | Q33: =INDEX(Script_List!$R$2:$R$161,MATCH(P33,Script_List!$A$2:$A$161,0)) -> 3 | R33: =INDEX(Script_List!$X$2:$X$161,MATCH(P33,Script_List!$A$2:$A$161,0)) -> 438 | T33: =Assumptions!B3 -> 2 | U33: =MAX(R32:R167) -> 648 | V33: =MAX(Q32:Q167) -> 10 | W33: =Assumptions!B4 -> 490
P34: SYN-005 | Q34: =INDEX(Script_List!$R$2:$R$161,MATCH(P34,Script_List!$A$2:$A$161,0)) -> 2 | R34: =INDEX(Script_List!$X$2:$X$161,MATCH(P34,Script_List!$A$2:$A$161,0)) -> 383
P35: SYN-006 | Q35: =INDEX(Script_List!$R$2:$R$161,MATCH(P35,Script_List!$A$2:$A$161,0)) -> 4 | R35: =INDEX(Script_List!$X$2:$X$161,MATCH(P35,Script_List!$A$2:$A$161,0)) -> 474
P36: SYN-008 | Q36: =INDEX(Script_List!$R$2:$R$161,MATCH(P36,Script_List!$A$2:$A$161,0)) -> 2 | R36: =INDEX(Script_List!$X$2:$X$161,MATCH(P36,Script_List!$A$2:$A$161,0)) -> 527
P37: SYN-009 | Q37: =INDEX(Script_List!$R$2:$R$161,MATCH(P37,Script_List!$A$2:$A$161,0)) -> 4 | R37: =INDEX(Script_List!$X$2:$X$161,MATCH(P37,Script_List!$A$2:$A$161,0)) -> 490
P38: SYN-010 | Q38: =INDEX(Script_List!$R$2:$R$161,MATCH(P38,Script_List!$A$2:$A$161,0)) -> 1 | R38: =INDEX(Script_List!$X$2:$X$161,MATCH(P38,Script_List!$A$2:$A$161,0)) -> 332
P39: SYN-011 | Q39: =INDEX(Script_List!$R$2:$R$161,MATCH(P39,Script_List!$A$2:$A$161,0)) -> 2 | R39: =INDEX(Script_List!$X$2:$X$161,MATCH(P39,Script_List!$A$2:$A$161,0)) -> 528
P40: SYN-012 | Q40: =INDEX(Script_List!$R$2:$R$161,MATCH(P40,Script_List!$A$2:$A$161,0)) -> 5 | R40: =INDEX(Script_List!$X$2:$X$161,MATCH(P40,Script_List!$A$2:$A$161,0)) -> 527
P41: SYN-013 | Q41: =INDEX(Script_List!$R$2:$R$161,MATCH(P41,Script_List!$A$2:$A$161,0)) -> 1 | R41: =INDEX(Script_List!$X$2:$X$161,MATCH(P41,Script_List!$A$2:$A$161,0)) -> 324
P42: SYN-014 | Q42: =INDEX(Script_List!$R$2:$R$161,MATCH(P42,Script_List!$A$2:$A$161,0)) -> 2 | R42: =INDEX(Script_List!$X$2:$X$161,MATCH(P42,Script_List!$A$2:$A$161,0)) -> 563
P43: SYN-015 | Q43: =INDEX(Script_List!$R$2:$R$161,MATCH(P43,Script_List!$A$2:$A$161,0)) -> 7 | R43: =INDEX(Script_List!$X$2:$X$161,MATCH(P43,Script_List!$A$2:$A$161,0)) -> 560
A44: Verified synthetic findings | P44: SYN-016 | Q44: =INDEX(Script_List!$R$2:$R$161,MATCH(P44,Script_List!$A$2:$A$161,0)) -> 1 | R44: =INDEX(Script_List!$X$2:$X$161,MATCH(P44,Script_List!$A$2:$A$161,0)) -> 648
A45: Full-month counts range from 29 to 32; seven months tie at 32. | P45: SYN-017 | Q45: =INDEX(Script_List!$R$2:$R$161,MATCH(P45,Script_List!$A$2:$A$161,0)) -> 3 | R45: =INDEX(Script_List!$X$2:$X$161,MATCH(P45,Script_List!$A$2:$A$161,0)) -> 482
A46: City-limited $505.50/session; exclusive $527.86; boxed $430.96. | P46: SYN-018 | Q46: =INDEX(Script_List!$R$2:$R$161,MATCH(P46,Script_List!$A$2:$A$161,0)) -> 10 | R46: =INDEX(Script_List!$X$2:$X$161,MATCH(P46,Script_List!$A$2:$A$161,0)) -> 332
A47: 136 of 160 scripts opened; October is partial (8 sessions). | P47: SYN-019 | Q47: =INDEX(Script_List!$R$2:$R$161,MATCH(P47,Script_List!$A$2:$A$161,0)) -> 1 | R47: =INDEX(Script_List!$X$2:$X$161,MATCH(P47,Script_List!$A$2:$A$161,0)) -> 609
P48: SYN-020 | Q48: =INDEX(Script_List!$R$2:$R$161,MATCH(P48,Script_List!$A$2:$A$161,0)) -> 3 | R48: =INDEX(Script_List!$X$2:$X$161,MATCH(P48,Script_List!$A$2:$A$161,0)) -> 564
...

Sheet Assumptions
A1: Assumption | B1: Value
A2: RMB Per USD | B2: 7.2
A3: Opened-script session median | B3: =MEDIAN(Pivot_Analysis!$N$2:$N$137) -> 2
A4: Opened-script contribution median | B4: =MEDIAN(Pivot_Analysis!$O$2:$O$137) -> 490
A5: Analysis start | B5: 45901
A6: Analysis end | B6: 46303
A7: Percentage wage factor | B7: 0.2625
A8: Wage rule | B8: Script wage inputs are total session wages; no extra DM-count multiplication.
A9: Acquisition convention | B9: USD acquisition costs rounded to whole dollars.
A10: Threshold population | B10: Opened scripts only. Median ties classified as high.
A11: Partial month | B11: October 2026 contains October 1–8 only.

Sheet Script_List
A1: Script ID | B1: Script Name | C1: Script Type | D1: DM | E1: Players | F1: Price Per Player | G1: Estimated Gross Revenue | H1: Standard DM Wage | I1: Script Edition | J1: Estimated Contribution | K1: Rating | L1: Cost Low(RMB) | M1: Cost Base(RMB) | N1: Cost High(RMB) | O1: Cost Low(USD) | P1: Cost Base(USD) | Q1: Cost High(USD) | R1: Observed Session Count | S1: Cumulative Estimated Contribution | T1: Surplus - Low Cost | U1: Surplus - Base Cost | V1: Surplus - High Cost | W1: Cost Recovery Status | X1: Average Contribution per Session | Y1: Open Session Count | Z1: Avg Contribution(Opened Only) | AA1: Strategy Segment
A2: SYN-001 | B2: Synthetic Script 001 | C2: 情感 | D2: 2 | E2: 6 | F2: 99 | G2: =E2*F2 -> 594 | H2: 180 | I2: 盒装 | J2: =G2-H2 -> 414 | K2: 7 | L2: 0 | M2: 750 | N2: 1000 | O2: =ROUND(L2/Assumptions!$B$2,0) -> 0 | P2: =ROUND(M2/Assumptions!$B$2,0) -> 104 | Q2: =ROUND(N2/Assumptions!$B$2,0) -> 139 | R2: =COUNTIF(RawData[Script ID],A2) -> 0 | S2: =SUMIF(RawData[Script ID],A2,RawData[Estimated Contribution]) -> 0 | T2: =S2-O2 -> 0 | U2: =S2-P2 -> -104 | V2: =S2-Q2 -> -139 | W2: =IF(R2=0,"Not Opened",IF(V2>=0,"Recovered - All Scenarios",IF(U2>=0,"Recovered - Low & Base",IF(T2>=0,"Recovered - Low Only","Not Recovered")))) -> Not Opened | X2: =IF(R2=0,0,S2/R2) -> 0 | Y2: =R2 -> 0 | Z2: =IF(R2=0,"",S2/R2) | AA2: =IF(R2=0,"Not Opened",IF(R2>=Assumptions!$B$3,"High Frequency","Low Frequency")&" / "&IF(X2>=Assumptions!$B$4,"High Contribution","Low Contribution")) -> Not Opened
A3: SYN-002 | B3: Synthetic Script 002 | C3: 推理 | D3: 1 | E3: 6 | F3: 75 | G3: =E3*F3 -> 450 | H3: 118 | I3: 城限 | J3: =G3-H3 -> 332 | K3: 7.7 | L3: 1500 | M3: 2000 | N3: 2500 | O3: =ROUND(L3/Assumptions!$B$2,0) -> 208 | P3: =ROUND(M3/Assumptions!$B$2,0) -> 278 | Q3: =ROUND(N3/Assumptions!$B$2,0) -> 347 | R3: =COUNTIF(RawData[Script ID],A3) -> 1 | S3: =SUMIF(RawData[Script ID],A3,RawData[Estimated Contribution]) -> 332 | T3: =S3-O3 -> 124 | U3: =S3-P3 -> 54 | V3: =S3-Q3 -> -15 | W3: =IF(R3=0,"Not Opened",IF(V3>=0,"Recovered - All Scenarios",IF(U3>=0,"Recovered - Low & Base",IF(T3>=0,"Recovered - Low Only","Not Recovered")))) -> Recovered - Low & Base | X3: =IF(R3=0,0,S3/R3) -> 332 | Y3: =R3 -> 1 | Z3: =IF(R3=0,"",S3/R3) -> 332 | AA3: =IF(R3=0,"Not Opened",IF(R3>=Assumptions!$B$3,"High Frequency","Low Frequency")&" / "&IF(X3>=Assumptions!$B$4,"High Contribution","Low Contribution")) -> Low Frequency / Low Contribution
A4: SYN-003 | B4: Synthetic Script 003 | C4: 情感 | D4: 3 | E4: 6 | F4: 118 | G4: =E4*F4 -> 708 | H4: 270 | I4: 盒装 | J4: =G4-H4 -> 438 | K4: 8.4 | L4: 0 | M4: 750 | N4: 1000 | O4: =ROUND(L4/Assumptions!$B$2,0) -> 0 | P4: =ROUND(M4/Assumptions!$B$2,0) -> 104 | Q4: =ROUND(N4/Assumptions!$B$2,0) -> 139 | R4: =COUNTIF(RawData[Script ID],A4) -> 3 | S4: =SUMIF(RawData[Script ID],A4,RawData[Estimated Contribution]) -> 1314 | T4: =S4-O4 -> 1314 | U4: =S4-P4 -> 1210 | V4: =S4-Q4 -> 1175 | W4: =IF(R4=0,"Not Opened",IF(V4>=0,"Recovered - All Scenarios",IF(U4>=0,"Recovered - Low & Base",IF(T4>=0,"Recovered - Low Only","Not Recovered")))) -> Recovered - All Scenarios | X4: =IF(R4=0,0,S4/R4) -> 438 | Y4: =R4 -> 3 | Z4: =IF(R4=0,"",S4/R4) -> 438 | AA4: =IF(R4=0,"Not Opened",IF(R4>=Assumptions!$B$3,"High Frequency","Low Frequency")&" / "&IF(X4>=Assumptions!$B$4,"High Contribution","Low Contribution")) -> High Frequency / Low Contribution
A5: SYN-004 | B5: Synthetic Script 004 | C5: 欢乐 | D5: 3 | E5: 7 | F5: 129 | G5: =E5*F5 -> 903 | H5: 237 | I5: 独家 | J5: =G5-H5 -> 666 | K5: 7 | L5: 2500 | M5: 3000 | N5: 3500 | O5: =ROUND(L5/Assumptions!$B$2,0) -> 347 | P5: =ROUND(M5/Assumptions!$B$2,0) -> 417 | Q5: =ROUND(N5/Assumptions!$B$2,0) -> 486 | R5: =COUNTIF(RawData[Script ID],A5) -> 0 | S5: =SUMIF(RawData[Script ID],A5,RawData[Estimated Contribution]) -> 0 | T5: =S5-O5 -> -347 | U5: =S5-P5 -> -417 | V5: =S5-Q5 -> -486 | W5: =IF(R5=0,"Not Opened",IF(V5>=0,"Recovered - All Scenarios",IF(U5>=0,"Recovered - Low & Base",IF(T5>=0,"Recovered - Low Only","Not Recovered")))) -> Not Opened | X5: =IF(R5=0,0,S5/R5) -> 0 | Y5: =R5 -> 0 | Z5: =IF(R5=0,"",S5/R5) | AA5: =IF(R5=0,"Not Opened",IF(R5>=Assumptions!$B$3,"High Frequency","Low Frequency")&" / "&IF(X5>=Assumptions!$B$4,"High Contribution","Low Contribution")) -> Not Opened
A6: SYN-005 | B6: Synthetic Script 005 | C6: 推理 | D6: 2 | E6: 8 | F6: 65 | G6: =E6*F6 -> 520 | H6: 137 | I6: 城限 | J6: =G6-H6 -> 383 | K6: 7.7 | L6: 1500 | M6: 2000 | N6: 2500 | O6: =ROUND(L6/Assumptions!$B$2,0) -> 208 | P6: =ROUND(M6/Assumptions!$B$2,0) -> 278 | Q6: =ROUND(N6/Assumptions!$B$2,0) -> 347 | R6: =COUNTIF(RawData[Script ID],A6) -> 2 | S6: =SUMIF(RawData[Script ID],A6,RawData[Estimated Contribution]) -> 766 | T6: =S6-O6 -> 558 | U6: =S6-P6 -> 488 | V6: =S6-Q6 -> 419 | W6: =IF(R6=0,"Not Opened",IF(V6>=0,"Recovered - All Scenarios",IF(U6>=0,"Recovered - Low & Base",IF(T6>=0,"Recovered - Low Only","Not Recovered")))) -> Recovered - All Scenarios | X6: =IF(R6=0,0,S6/R6) -> 383 | Y6: =R6 -> 2 | Z6: =IF(R6=0,"",S6/R6) -> 383 | AA6: =IF(R6=0,"Not Opened",IF(R6>=Assumptions!$B$3,"High Frequency","Low Frequency")&" / "&IF(X6>=Assumptions!$B$4,"High Contribution","Low Contribution")) -> High Frequency / Low Contribution
A7: SYN-006 | B7: Synthetic Script 006 | C7: 情感 | D7: 2 | E7: 6 | F7: 109 | G7: =E7*F7 -> 654 | H7: 180 | I7: 盒装 | J7: =G7-H7 -> 474 | K7: 8.4 | L7: 0 | M7: 750 | N7: 1000 | O7: =ROUND(L7/Assumptions!$B$2,0) -> 0 | P7: =ROUND(M7/Assumptions!$B$2,0) -> 104 | Q7: =ROUND(N7/Assumptions!$B$2,0) -> 139 | R7: =COUNTIF(RawData[Script ID],A7) -> 4 | S7: =SUMIF(RawData[Script ID],A7,RawData[Estimated Contribution]) -> 1896 | T7: =S7-O7 -> 1896 | U7: =S7-P7 -> 1792 | V7: =S7-Q7 -> 1757 | W7: =IF(R7=0,"Not Opened",IF(V7>=0,"Recovered - All Scenarios",IF(U7>=0,"Recovered - Low & Base",IF(T7>=0,"Recovered - Low Only","Not Recovered")))) -> Recovered - All Scenarios | X7: =IF(R7=0,0,S7/R7) -> 474 | Y7: =R7 -> 4 | Z7: =IF(R7=0,"",S7/R7) -> 474 | AA7: =IF(R7=0,"Not Opened",IF(R7>=Assumptions!$B$3,"High Frequency","Low Frequency")&" / "&IF(X7>=Assumptions!$B$4,"High Contribution","Low Contribution")) -> High Frequency / Low Contribution
A8: SYN-007 | B8: Synthetic Script 007 | C8: 机制 | D8: 1 | E8: 6 | F8: 129 | G8: =E8*F8 -> 774 | H8: 203 | I8: 城限 | J8: =G8-H8 -> 571 | K8: 7 | L8: 1500 | M8: 2000 | N8: 2500 | O8: =ROUND(L8/Assumptions!$B$2,0) -> 208 | P8: =ROUND(M8/Assumptions!$B$2,0) -> 278 | Q8: =ROUND(N8/Assumptions!$B$2,0) -> 347 | R8: =COUNTIF(RawData[Script ID],A8) -> 0 | S8: =SUMIF(RawData[Script ID],A8,RawData[Estimated Contribution]) -> 0 | T8: =S8-O8 -> -208 | U8: =S8-P8 -> -278 | V8: =S8-Q8 -> -347 | W8: =IF(R8=0,"Not Opened",IF(V8>=0,"Recovered - All Scenarios",IF(U8>=0,"Recovered - Low & Base",IF(T8>=0,"Recovered - Low Only","Not Recovered")))) -> Not Opened | X8: =IF(R8=0,0,S8/R8) -> 0 | Y8: =R8 -> 0 | Z8: =IF(R8=0,"",S8/R8) | AA8: =IF(R8=0,"Not Opened",IF(R8>=Assumptions!$B$3,"High Frequency","Low Frequency")&" / "&IF(X8>=Assumptions!$B$4,"High Contribution","Low Contribution")) -> Not Opened
A9: SYN-008 | B9: Synthetic Script 008 | C9: 推理 | D9: 1 | E9: 6 | F9: 119 | G9: =E9*F9 -> 714 | H9: 187 | I9: 盒装 | J9: =G9-H9 -> 527 | K9: 7.7 | L9: 0 | M9: 750 | N9: 1000 | O9: =ROUND(L9/Assumptions!$B$2,0) -> 0 | P9: =ROUND(M9/Assumptions!$B$2,0) -> 104 | Q9: =ROUND(N9/Assumptions!$B$2,0) -> 139 | R9: =COUNTIF(RawData[Script ID],A9) -> 2 | S9: =SUMIF(RawData[Script ID],A9,RawData[Estimated Contribution]) -> 1054 | T9: =S9-O9 -> 1054 | U9: =S9-P9 -> 950 | V9: =S9-Q9 -> 915 | W9: =IF(R9=0,"Not Opened",IF(V9>=0,"Recovered - All Scenarios",IF(U9>=0,"Recovered - Low & Base",IF(T9>=0,"Recovered - Low Only","Not Recovered")))) -> Recovered - All Scenarios | X9: =IF(R9=0,0,S9/R9) -> 527 | Y9: =R9 -> 2 | Z9: =IF(R9=0,"",S9/R9) -> 527 | AA9: =IF(R9=0,"Not Opened",IF(R9>=Assumptions!$B$3,"High Frequency","Low Frequency")&" / "&IF(X9>=Assumptions!$B$4,"High Contribution","Low Contribution")) -> High Frequency / High Contribution
A10: SYN-009 | B10: Synthetic Script 009 | C10: 欢乐 | D10: 3 | E10: 7 | F10: 95 | G10: =E10*F10 -> 665 | H10: 175 | I10: 独家 | J10: =G10-H10 -> 490 | K10: 8.4 | L10: 2500 | M10: 3000 | N10: 3500 | O10: =ROUND(L10/Assumptions!$B$2,0) -> 347 | P10: =ROUND(M10/Assumptions!$B$2,0) -> 417 | Q10: =ROUND(N10/Assumptions!$B$2,0) -> 486 | R10: =COUNTIF(RawData[Script ID],A10) -> 4 | S10: =SUMIF(RawData[Script ID],A10,RawData[Estimated Contribution]) -> 1960 | T10: =S10-O10 -> 1613 | U10: =S10-P10 -> 1543 | V10: =S10-Q10 -> 1474 | W10: =IF(R10=0,"Not Opened",IF(V10>=0,"Recovered - All Scenarios",IF(U10>=0,"Recovered - Low & Base",IF(T10>=0,"Recovered - Low Only","Not Recovered")))) -> Recovered - All Scenarios | X10: =IF(R10=0,0,S10/R10) -> 490 | Y10: =R10 -> 4 | Z10: =IF(R10=0,"",S10/R10) -> 490 | AA10: =IF(R10=0,"Not Opened",IF(R10>=Assumptions!$B$3,"High Frequency","Low Frequency")&" / "&IF(X10>=Assumptions!$B$4,"High Contribution","Low Contribution")) -> High Frequency / High Contribution
A11: SYN-010 | B11: Synthetic Script 010 | C11: 情感 | D11: 6 | E11: 8 | F11: 109 | G11: =E11*F11 -> 872 | H11: 540 | I11: 盒装 | J11: =G11-H11 -> 332 | K11: 7 | L11: 0 | M11: 750 | N11: 1000 | O11: =ROUND(L11/Assumptions!$B$2,0) -> 0 | P11: =ROUND(M11/Assumptions!$B$2,0) -> 104 | Q11: =ROUND(N11/Assumptions!$B$2,0) -> 139 | R11: =COUNTIF(RawData[Script ID],A11) -> 1 | S11: =SUMIF(RawData[Script ID],A11,RawData[Estimated Contribution]) -> 332 | T11: =S11-O11 -> 332 | U11: =S11-P11 -> 228 | V11: =S11-Q11 -> 193 | W11: =IF(R11=0,"Not Opened",IF(V11>=0,"Recovered - All Scenarios",IF(U11>=0,"Recovered - Low & Base",IF(T11>=0,"Recovered - Low Only","Not Recovered")))) -> Recovered - All Scenarios | X11: =IF(R11=0,0,S11/R11) -> 332 | Y11: =R11 -> 1 | Z11: =IF(R11=0,"",S11/R11) -> 332 | AA11: =IF(R11=0,"Not Opened",IF(R11>=Assumptions!$B$3,"High Frequency","Low Frequency")&" / "&IF(X11>=Assumptions!$B$4,"High Contribution","Low Contribution")) -> Low Frequency / Low Contribution
A12: SYN-011 | B12: Synthetic Script 011 | C12: 情感 | D12: 2 | E12: 6 | F12: 118 | G12: =E12*F12 -> 708 | H12: 180 | I12: 盒装 | J12: =G12-H12 -> 528 | K12: 7.7 | L12: 0 | M12: 750 | N12: 1000 | O12: =ROUND(L12/Assumptions!$B$2,0) -> 0 | P12: =ROUND(M12/Assumptions!$B$2,0) -> 104 | Q12: =ROUND(N12/Assumptions!$B$2,0) -> 139 | R12: =COUNTIF(RawData[Script ID],A12) -> 2 | S12: =SUMIF(RawData[Script ID],A12,RawData[Estimated Contribution]) -> 1056 | T12: =S12-O12 -> 1056 | U12: =S12-P12 -> 952 | V12: =S12-Q12 -> 917 | W12: =IF(R12=0,"Not Opened",IF(V12>=0,"Recovered - All Scenarios",IF(U12>=0,"Recovered - Low & Base",IF(T12>=0,"Recovered - Low Only","Not Recovered")))) -> Recovered - All Scenarios | X12: =IF(R12=0,0,S12/R12) -> 528 | Y12: =R12 -> 2 | Z12: =IF(R12=0,"",S12/R12) -> 528 | AA12: =IF(R12=0,"Not Opened",IF(R12>=Assumptions!$B$3,"High Frequency","Low Frequency")&" / "&IF(X12>=Assumptions!$B$4,"High Contribution","Low Contribution")) -> High Frequency / High Contribution
A13: SYN-012 | B13: Synthetic Script 012 | C13: 推理 | D13: 1 | E13: 6 | F13: 119 | G13: =E13*F13 -> 714 | H13: 187 | I13: 城限 | J13: =G13-H13 -> 527 | K13: 8.4 | L13: 1500 | M13: 2000 | N13: 2500 | O13: =ROUND(L13/Assumptions!$B$2,0) -> 208 | P13: =ROUND(M13/Assumptions!$B$2,0) -> 278 | Q13: =ROUND(N13/Assumptions!$B$2,0) -> 347 | R13: =COUNTIF(RawData[Script ID],A13) -> 5 | S13: =SUMIF(RawData[Script ID],A13,RawData[Estimated Contribution]) -> 2635 | T13: =S13-O13 -> 2427 | U13: =S13-P13 -> 2357 | V13: =S13-Q13 -> 2288 | W13: =IF(R13=0,"Not Opened",IF(V13>=0,"Recovered - All Scenarios",IF(U13>=0,"Recovered - Low & Base",IF(T13>=0,"Recovered - Low Only","Not Recovered")))) -> Recovered - All Scenarios | X13: =IF(R13=0,0,S13/R13) -> 527 | Y13: =R13 -> 5 | Z13: =IF(R13=0,"",S13/R13) -> 527 | AA13: =IF(R13=0,"Not Opened",IF(R13>=Assumptions!$B$3,"High Frequency","Low Frequency")&" / "&IF(X13>=Assumptions!$B$4,"High Contribution","Low Contribution")) -> High Frequency / High Contribution
... A161: SYN-160 | B161: Synthetic Script 160 | C161: 情感 | D161: 6 | E161: 8 | F161: 138 | G161: =E161*F161 -> 1104 | H161: 540 | I161: 盒装 | J161: =G161-H161 -> 564 | K161: 7 | L161: 0 | M161: 750 | N161: 1000 | O161: =ROUND(L161/Assumptions!$B$2,0) -> 0 | P161: =ROUND(M161/Assumptions!$B$2,0) -> 104 | Q161: =ROUND(N161/Assumptions!$B$2,0) -> 139 | R161: =COUNTIF(RawData[Script ID],A161) -> 3 | S161: =SUMIF(RawData[Script ID],A161,RawData[Estimated Contribution]) -> 1692 | T161: =S161-O161 -> 1692 | U161: =S161-P161 -> 1588 | V161: =S161-Q161 -> 1553 | W161: =IF(R161=0,"Not Opened",IF(V161>=0,"Recovered - All Scenarios",IF(U161>=0,"Recovered - Low & Base",IF(T161>=0,"Recovered - Low Only","Not Recovered")))) -> Recovered - All Scenarios | X161: =IF(R161=0,0,S161/R161) -> 564 | Y161: =R161 -> 3 | Z161: =IF(R161=0,"",S161/R161) -> 564 | AA161: =IF(R161=0,"Not Opened",IF(R161>=Assumptions!$B$3,"High Frequency","Low Frequency")&" / "&IF(X161>=Assumptions!$B$4,"High Contribution","Low Contribution")) -> High Frequency / High Contribution

Sheet Raw Data
A1: Session ID | B1: Script ID | C1: Date | D1: Script Name | E1: Script Type | F1: DM Count | G1: Players | H1: Price Per Player | I1: Estimated Gross Revenue | J1: Standard DM Wage | K1: Script Edition | L1: Estimated Contribution | M1: Rating | N1: Month Start | O1: Report Month
A2: SES-0001 | B2: SYN-002 | C2: 45901 | D2: Synthetic Script 002 | E2: 推理 | F2: 1 | G2: 6 | H2: 75 | I2: =G2*H2 -> 450 | J2: =INDEX(Script_List!$H$2:$H$161,MATCH(B2,Script_List!$A$2:$A$161,0)) -> 118 | K2: 城限 | L2: =I2-J2 -> 332 | M2: 7.7 | N2: =DATE(YEAR(C2),MONTH(C2),1) -> 45901 | O2: =TEXT(N2,"yyyy-mm") -> 2025-09
A3: SES-0002 | B3: SYN-003 | C3: 45902 | D3: Synthetic Script 003 | E3: 情感 | F3: 3 | G3: 6 | H3: 118 | I3: =G3*H3 -> 708 | J3: =INDEX(Script_List!$H$2:$H$161,MATCH(B3,Script_List!$A$2:$A$161,0)) -> 270 | K3: 盒装 | L3: =I3-J3 -> 438 | M3: 8.4 | N3: =DATE(YEAR(C3),MONTH(C3),1) -> 45901 | O3: =TEXT(N3,"yyyy-mm") -> 2025-09
A4: SES-0003 | B4: SYN-003 | C4: 45903 | D4: Synthetic Script 003 | E4: 情感 | F4: 3 | G4: 6 | H4: 118 | I4: =G4*H4 -> 708 | J4: =INDEX(Script_List!$H$2:$H$161,MATCH(B4,Script_List!$A$2:$A$161,0)) -> 270 | K4: 盒装 | L4: =I4-J4 -> 438 | M4: 8.4 | N4: =DATE(YEAR(C4),MONTH(C4),1) -> 45901 | O4: =TEXT(N4,"yyyy-mm") -> 2025-09
A5: SES-0004 | B5: SYN-003 | C5: 45904 | D5: Synthetic Script 003 | E5: 情感 | F5: 3 | G5: 6 | H5: 118 | I5: =G5*H5 -> 708 | J5: =INDEX(Script_List!$H$2:$H$161,MATCH(B5,Script_List!$A$2:$A$161,0)) -> 270 | K5: 盒装 | L5: =I5-J5 -> 438 | M5: 8.4 | N5: =DATE(YEAR(C5),MONTH(C5),1) -> 45901 | O5: =TEXT(N5,"yyyy-mm") -> 2025-09
A6: SES-0005 | B6: SYN-005 | C6: 45905 | D6: Synthetic Script 005 | E6: 推理 | F6: 2 | G6: 8 | H6: 65 | I6: =G6*H6 -> 520 | J6: =INDEX(Script_List!$H$2:$H$161,MATCH(B6,Script_List!$A$2:$A$161,0)) -> 137 | K6: 城限 | L6: =I6-J6 -> 383 | M6: 7.7 | N6: =DATE(YEAR(C6),MONTH(C6),1) -> 45901 | O6: =TEXT(N6,"yyyy-mm") -> 2025-09
A7: SES-0006 | B7: SYN-005 | C7: 45906 | D7: Synthetic Script 005 | E7: 推理 | F7: 2 | G7: 8 | H7: 65 | I7: =G7*H7 -> 520 | J7: =INDEX(Script_List!$H$2:$H$161,MATCH(B7,Script_List!$A$2:$A$161,0)) -> 137 | K7: 城限 | L7: =I7-J7 -> 383 | M7: 7.7 | N7: =DATE(YEAR(C7),MONTH(C7),1) -> 45901 | O7: =TEXT(N7,"yyyy-mm") -> 2025-09
A8: SES-0007 | B8: SYN-006 | C8: 45907 | D8: Synthetic Script 006 | E8: 情感 | F8: 2 | G8: 6 | H8: 109 | I8: =G8*H8 -> 654 | J8: =INDEX(Script_List!$H$2:$H$161,MATCH(B8,Script_List!$A$2:$A$161,0)) -> 180 | K8: 盒装 | L8: =I8-J8 -> 474 | M8: 8.4 | N8: =DATE(YEAR(C8),MONTH(C8),1) -> 45901 | O8: =TEXT(N8,"yyyy-mm") -> 2025-09
A9: SES-0008 | B9: SYN-006 | C9: 45908 | D9: Synthetic Script 006 | E9: 情感 | F9: 2 | G9: 6 | H9: 109 | I9: =G9*H9 -> 654 | J9: =INDEX(Script_List!$H$2:$H$161,MATCH(B9,Script_List!$A$2:$A$161,0)) -> 180 | K9: 盒装 | L9: =I9-J9 -> 474 | M9: 8.4 | N9: =DATE(YEAR(C9),MONTH(C9),1) -> 45901 | O9: =TEXT(N9,"yyyy-mm") -> 2025-09
A10: SES-0009 | B10: SYN-006 | C10: 45909 | D10: Synthetic Script 006 | E10: 情感 | F10: 2 | G10: 6 | H10: 109 | I10: =G10*H10 -> 654 | J10: =INDEX(Script_List!$H$2:$H$161,MATCH(B10,Script_List!$A$2:$A$161,0)) -> 180 | K10: 盒装 | L10: =I10-J10 -> 474 | M10: 8.4 | N10: =DATE(YEAR(C10),MONTH(C10),1) -> 45901 | O10: =TEXT(N10,"yyyy-mm") -> 2025-09
A11: SES-0010 | B11: SYN-006 | C11: 45910 | D11: Synthetic Script 006 | E11: 情感 | F11: 2 | G11: 6 | H11: 109 | I11: =G11*H11 -> 654 | J11: =INDEX(Script_List!$H$2:$H$161,MATCH(B11,Script_List!$A$2:$A$161,0)) -> 180 | K11: 盒装 | L11: =I11-J11 -> 474 | M11: 8.4 | N11: =DATE(YEAR(C11),MONTH(C11),1) -> 45901 | O11: =TEXT(N11,"yyyy-mm") -> 2025-09
A12: SES-0011 | B12: SYN-008 | C12: 45911 | D12: Synthetic Script 008 | E12: 推理 | F12: 1 | G12: 6 | H12: 119 | I12: =G12*H12 -> 714 | J12: =INDEX(Script_List!$H$2:$H$161,MATCH(B12,Script_List!$A$2:$A$161,0)) -> 187 | K12: 盒装 | L12: =I12-J12 -> 527 | M12: 7.7 | N12: =DATE(YEAR(C12),MONTH(C12),1) -> 45901 | O12: =TEXT(N12,"yyyy-mm") -> 2025-09
A13: SES-0012 | B13: SYN-008 | C13: 45912 | D13: Synthetic Script 008 | E13: 推理 | F13: 1 | G13: 6 | H13: 119 | I13: =G13*H13 -> 714 | J13: =INDEX(Script_List!$H$2:$H$161,MATCH(B13,Script_List!$A$2:$A$161,0)) -> 187 | K13: 盒装 | L13: =I13-J13 -> 527 | M13: 7.7 | N13: =DATE(YEAR(C13),MONTH(C13),1) -> 45901 | O13: =TEXT(N13,"yyyy-mm") -> 2025-09
... A417: SES-0416 | B417: SYN-160 | C417: 46303 | D417: Synthetic Script 160 | E417: 情感 | F417: 6 | G417: 8 | H417: 138 | I417: =G417*H417 -> 1104 | J417: =INDEX(Script_List!$H$2:$H$161,MATCH(B417,Script_List!$A$2:$A$161,0)) -> 540 | K417: 盒装 | L417: =I417-J417 -> 564 | M417: 7 | N417: =DATE(YEAR(C417),MONTH(C417),1) -> 46296 | O417: =TEXT(N417,"yyyy-mm") -> 2026-10

Sheet Pivot_Analysis
A1: Synthetic analysis summaries; Refresh All after changing inputs | M1: Opened Script ID | N1: Observed Sessions | O1: Average Contribution
M2: SYN-002 | N2: =INDEX(Script_List!$R$2:$R$161,MATCH(M2,Script_List!$A$2:$A$161,0)) -> 1 | O2: =INDEX(Script_List!$X$2:$X$161,MATCH(M2,Script_List!$A$2:$A$161,0)) -> 332
A3: Script | B3: Observed Sessions | E3: Script Type | F3: Session Count | G3: Estimated Revenue | H3: Estimated Contribution | I3: Contribution / Session | M3: SYN-003 | N3: =INDEX(Script_List!$R$2:$R$161,MATCH(M3,Script_List!$A$2:$A$161,0)) -> 3 | O3: =INDEX(Script_List!$X$2:$X$161,MATCH(M3,Script_List!$A$2:$A$161,0)) -> 438
A4: Synthetic Script 018 | B4: 10 | E4: 情感 | F4: 120 | G4: 94096 | H4: 58096 | I4: 484.13333 | M4: SYN-005 | N4: =INDEX(Script_List!$R$2:$R$161,MATCH(M4,Script_List!$A$2:$A$161,0)) -> 2 | O4: =INDEX(Script_List!$X$2:$X$161,MATCH(M4,Script_List!$A$2:$A$161,0)) -> 383
A5: Synthetic Script 038 | B5: 10 | E5: 推理 | F5: 216 | G5: 130464 | H5: 96216 | I5: 445.44444 | M5: SYN-006 | N5: =INDEX(Script_List!$R$2:$R$161,MATCH(M5,Script_List!$A$2:$A$161,0)) -> 4 | O5: =INDEX(Script_List!$X$2:$X$161,MATCH(M5,Script_List!$A$2:$A$161,0)) -> 474
A6: Synthetic Script 058 | B6: 10 | E6: 机制 | F6: 24 | G6: 15696 | H6: 11568 | I6: 482 | M6: SYN-008 | N6: =INDEX(Script_List!$R$2:$R$161,MATCH(M6,Script_List!$A$2:$A$161,0)) -> 2 | O6: =INDEX(Script_List!$X$2:$X$161,MATCH(M6,Script_List!$A$2:$A$161,0)) -> 527
A7: Synthetic Script 078 | B7: 10 | E7: 欢乐 | F7: 56 | G7: 40096 | H7: 29560 | I7: 527.85714 | M7: SYN-009 | N7: =INDEX(Script_List!$R$2:$R$161,MATCH(M7,Script_List!$A$2:$A$161,0)) -> 4 | O7: =INDEX(Script_List!$X$2:$X$161,MATCH(M7,Script_List!$A$2:$A$161,0)) -> 490
A8: Synthetic Script 098 | B8: 10 | E8: Grand Total | F8: 416 | G8: 280352 | H8: 195440 | I8: 469.80769 | M8: SYN-010 | N8: =INDEX(Script_List!$R$2:$R$161,MATCH(M8,Script_List!$A$2:$A$161,0)) -> 1 | O8: =INDEX(Script_List!$X$2:$X$161,MATCH(M8,Script_List!$A$2:$A$161,0)) -> 332
A9: Synthetic Script 118 | B9: 10 | M9: SYN-011 | N9: =INDEX(Script_List!$R$2:$R$161,MATCH(M9,Script_List!$A$2:$A$161,0)) -> 2 | O9: =INDEX(Script_List!$X$2:$X$161,MATCH(M9,Script_List!$A$2:$A$161,0)) -> 528
A10: Synthetic Script 138 | B10: 10 | M10: SYN-012 | N10: =INDEX(Script_List!$R$2:$R$161,MATCH(M10,Script_List!$A$2:$A$161,0)) -> 5 | O10: =INDEX(Script_List!$X$2:$X$161,MATCH(M10,Script_List!$A$2:$A$161,0)) -> 527
A11: Synthetic Script 158 | B11: 10 | M11: SYN-013 | N11: =INDEX(Script_List!$R$2:$R$161,MATCH(M11,Script_List!$A$2:$A$161,0)) -> 1 | O11: =INDEX(Script_List!$X$2:$X$161,MATCH(M11,Script_List!$A$2:$A$161,0)) -> 324
A12: Synthetic Script 015 | B12: 7 | M12: SYN-014 | N12: =INDEX(Script_List!$R$2:$R$161,MATCH(M12,Script_List!$A$2:$A$161,0)) -> 2 | O12: =INDEX(Script_List!$X$2:$X$161,MATCH(M12,Script_List!$A$2:$A$161,0)) -> 563
A13: Synthetic Script 035 | B13: 7 | M13: SYN-015 | N13: =INDEX(Script_List!$R$2:$R$161,MATCH(M13,Script_List!$A$2:$A$161,0)) -> 7 | O13: =INDEX(Script_List!$X$2:$X$161,MATCH(M13,Script_List!$A$2:$A$161,0)) -> 560
A14: Synthetic Script 055 | B14: 7 | M14: SYN-016 | N14: =INDEX(Script_List!$R$2:$R$161,MATCH(M14,Script_List!$A$2:$A$161,0)) -> 1 | O14: =INDEX(Script_List!$X$2:$X$161,MATCH(M14,Script_List!$A$2:$A$161,0)) -> 648
A15: Synthetic Script 075 | B15: 7 | M15: SYN-017 | N15: =INDEX(Script_List!$R$2:$R$161,MATCH(M15,Script_List!$A$2:$A$161,0)) -> 3 | O15: =INDEX(Script_List!$X$2:$X$161,MATCH(M15,Script_List!$A$2:$A$161,0)) -> 482
A16: Synthetic Script 095 | B16: 7 | M16: SYN-018 | N16: =INDEX(Script_List!$R$2:$R$161,MATCH(M16,Script_List!$A$2:$A$161,0)) -> 10 | O16: =INDEX(Script_List!$X$2:$X$161,MATCH(M16,Script_List!$A$2:$A$161,0)) -> 332
A17: Synthetic Script 115 | B17: 7 | M17: SYN-019 | N17: =INDEX(Script_List!$R$2:$R$161,MATCH(M17,Script_List!$A$2:$A$161,0)) -> 1 | O17: =INDEX(Script_List!$X$2:$X$161,MATCH(M17,Script_List!$A$2:$A$161,0)) -> 609
A18: Synthetic Script 135 | B18: 7 | M18: SYN-020 | N18: =INDEX(Script_List!$R$2:$R$161,MATCH(M18,Script_List!$A$2:$A$161,0)) -> 3 | O18: =INDEX(Script_List!$X$2:$X$161,MATCH(M18,Script_List!$A$2:$A$161,0)) -> 564
A19: Synthetic Script 155 | B19: 7 | M19: SYN-022 | N19: =INDEX(Script_List!$R$2:$R$161,MATCH(M19,Script_List!$A$2:$A$161,0)) -> 1 | O19: =INDEX(Script_List!$X$2:$X$161,MATCH(M19,Script_List!$A$2:$A$161,0)) -> 332
A20: Synthetic Script 012 | B20: 5 | M20: SYN-023 | N20: =INDEX(Script_List!$R$2:$R$161,MATCH(M20,Script_List!$A$2:$A$161,0)) -> 3 | O20: =INDEX(Script_List!$X$2:$X$161,MATCH(M20,Script_List!$A$2:$A$161,0)) -> 438
... A23: Synthetic Script 072 | B23: 5 | M23: SYN-028 | N23: =INDEX(Script_List!$R$2:$R$161,MATCH(M23,Script_List!$A$2:$A$161,0)) -> 2 | O23: =INDEX(Script_List!$X$2:$X$161,MATCH(M23,Script_List!$A$2:$A$161,0)) -> 527
M24: SYN-029 | N24: =INDEX(Script_List!$R$2:$R$161,MATCH(M24,Script_List!$A$2:$A$161,0)) -> 4 | O24: =INDEX(Script_List!$X$2:$X$161,MATCH(M24,Script_List!$A$2:$A$161,0)) -> 490
M25: SYN-030 | N25: =INDEX(Script_List!$R$2:$R$161,MATCH(M25,Script_List!$A$2:$A$161,0)) -> 1 | O25: =INDEX(Script_List!$X$2:$X$161,MATCH(M25,Script_List!$A$2:$A$161,0)) -> 332
M26: SYN-031 | N26: =INDEX(Script_List!$R$2:$R$161,MATCH(M26,Script_List!$A$2:$A$161,0)) -> 2 | O26: =INDEX(Script_List!$X$2:$X$161,MATCH(M26,Script_List!$A$2:$A$161,0)) -> 528
M27: SYN-032 | N27: =INDEX(Script_List!$R$2:$R$161,MATCH(M27,Script_List!$A$2:$A$161,0)) -> 5 | O27: =INDEX(Script_List!$X$2:$X$161,MATCH(M27,Script_List!$A$2:$A$161,0)) -> 527
M28: SYN-033 | N28: =INDEX(Script_List!$R$2:$R$161,MATCH(M28,Script_List!$A$2:$A$161,0)) -> 1 | O28: =INDEX(Script_List!$X$2:$X$161,MATCH(M28,Script_List!$A$2:$A$161,0)) -> 324
M29: SYN-034 | N29: =INDEX(Script_List!$R$2:$R$161,MATCH(M29,Script_List!$A$2:$A$161,0)) -> 2 | O29: =INDEX(Script_List!$X$2:$X$161,MATCH(M29,Script_List!$A$2:$A$161,0)) -> 563
M30: SYN-035 | N30: =INDEX(Script_List!$R$2:$R$161,MATCH(M30,Script_List!$A$2:$A$161,0)) -> 7 | O30: =INDEX(Script_List!$X$2:$X$161,MATCH(M30,Script_List!$A$2:$A$161,0)) -> 560
M31: SYN-036 | N31: =INDEX(Script_List!$R$2:$R$161,MATCH(M31,Script_List!$A$2:$A$161,0)) -> 1 | O31: =INDEX(Script_List!$X$2:$X$161,MATCH(M31,Script_List!$A$2:$A$161,0)) -> 648
M32: SYN-037 | N32: =INDEX(Script_List!$R$2:$R$161,MATCH(M32,Script_List!$A$2:$A$161,0)) -> 3 | O32: =INDEX(Script_List!$X$2:$X$161,MATCH(M32,Script_List!$A$2:$A$161,0)) -> 482
M33: SYN-038 | N33: =INDEX(Script_List!$R$2:$R$161,MATCH(M33,Script_List!$A$2:$A$161,0)) -> 10 | O33: =INDEX(Script_List!$X$2:$X$161,MATCH(M33,Script_List!$A$2:$A$161,0)) -> 332
M34: SYN-039 | N34: =INDEX(Script_List!$R$2:$R$161,MATCH(M34,Script_List!$A$2:$A$161,0)) -> 1 | O34: =INDEX(Script_List!$X$2:$X$161,MATCH(M34,Script_List!$A$2:$A$161,0)) -> 609
A35: Report Month | B35: Session Count | F35: Script Edition | G35: Contribution / Session | H35: Session Count | M35: SYN-040 | N35: =INDEX(Script_List!$R$2:$R$161,MATCH(M35,Script_List!$A$2:$A$161,0)) -> 3 | O35: =INDEX(Script_List!$X$2:$X$161,MATCH(M35,Script_List!$A$2:$A$161,0)) -> 564
A36: 2025-09 | B36: 31 | F36: 城限 | G36: 505.5 | H36: 144 | M36: SYN-042 | N36: =INDEX(Script_List!$R$2:$R$161,MATCH(M36,Script_List!$A$2:$A$161,0)) -> 1 | O36: =INDEX(Script_List!$X$2:$X$161,MATCH(M36,Script_List!$A$2:$A$161,0)) -> 332
A37: 2025-10 | B37: 32 | F37: 独家 | G37: 527.85714 | H37: 56 | M37: SYN-043 | N37: =INDEX(Script_List!$R$2:$R$161,MATCH(M37,Script_List!$A$2:$A$161,0)) -> 3 | O37: =INDEX(Script_List!$X$2:$X$161,MATCH(M37,Script_List!$A$2:$A$161,0)) -> 438
A38: 2025-11 | B38: 31 | F38: 盒装 | G38: 430.96296 | H38: 216 | M38: SYN-045 | N38: =INDEX(Script_List!$R$2:$R$161,MATCH(M38,Script_List!$A$2:$A$161,0)) -> 2 | O38: =INDEX(Script_List!$X$2:$X$161,MATCH(M38,Script_List!$A$2:$A$161,0)) -> 383
A39: 2025-12 | B39: 32 | F39: Grand Total | G39: 469.80769 | H39: 416 | M39: SYN-046 | N39: =INDEX(Script_List!$R$2:$R$161,MATCH(M39,Script_List!$A$2:$A$161,0)) -> 4 | O39: =INDEX(Script_List!$X$2:$X$161,MATCH(M39,Script_List!$A$2:$A$161,0)) -> 474
A40: 2026-01 | B40: 32 | M40: SYN-048 | N40: =INDEX(Script_List!$R$2:$R$161,MATCH(M40,Script_List!$A$2:$A$161,0)) -> 2 | O40: =INDEX(Script_List!$X$2:$X$161,MATCH(M40,Script_List!$A$2:$A$161,0)) -> 527
A41: 2026-02 | B41: 29 | M41: SYN-049 | N41: =INDEX(Script_List!$R$2:$R$161,MATCH(M41,Script_List!$A$2:$A$161,0)) -> 4 | O41: =INDEX(Script_List!$X$2:$X$161,MATCH(M41,Script_List!$A$2:$A$161,0)) -> 490
A42: 2026-03 | B42: 32 | M42: SYN-050 | N42: =INDEX(Script_List!$R$2:$R$161,MATCH(M42,Script_List!$A$2:$A$161,0)) -> 1 | O42: =INDEX(Script_List!$X$2:$X$161,MATCH(M42,Script_List!$A$2:$A$161,0)) -> 332
...

Sheet Checks
A1: Check | B1: Calculated | C1: Expected | D1: Difference | F1: Session ID | G1: Unmatched ID | H1: Duplicate ID
A2: Session count | B2: =COUNTA(RawData[Session ID]) -> 416 | C2: 416 | D2: =B2-C2 -> 0 | F2: SES-0001 | G2: =IF(COUNTIF(Script_List[Script ID],'Raw Data'!B2)=1,0,1) -> 0 | H2: =IF(COUNTIF(RawData[Session ID],F2)=1,0,1) -> 0
A3: Revenue | B3: =SUM(RawData[Estimated Gross Revenue]) -> 280352 | C3: 280352 | D3: =B3-C3 -> 0 | F3: SES-0002 | G3: =IF(COUNTIF(Script_List[Script ID],'Raw Data'!B3)=1,0,1) -> 0 | H3: =IF(COUNTIF(RawData[Session ID],F3)=1,0,1) -> 0
A4: Contribution | B4: =SUM(RawData[Estimated Contribution]) -> 195440 | C4: 195440 | D4: =B4-C4 -> 0 | F4: SES-0003 | G4: =IF(COUNTIF(Script_List[Script ID],'Raw Data'!B4)=1,0,1) -> 0 | H4: =IF(COUNTIF(RawData[Session ID],F4)=1,0,1) -> 0
A5: Script count | B5: =COUNTA(Script_List[Script ID]) -> 160 | C5: 160 | D5: =B5-C5 -> 0 | F5: SES-0004 | G5: =IF(COUNTIF(Script_List[Script ID],'Raw Data'!B5)=1,0,1) -> 0 | H5: =IF(COUNTIF(RawData[Session ID],F5)=1,0,1) -> 0
A6: Opened scripts | B6: =COUNTIF(Script_List[Observed Session Count],">0") -> 136 | C6: 136 | D6: =B6-C6 -> 0 | F6: SES-0005 | G6: =IF(COUNTIF(Script_List[Script ID],'Raw Data'!B6)=1,0,1) -> 0 | H6: =IF(COUNTIF(RawData[Session ID],F6)=1,0,1) -> 0
A7: Unmatched script IDs | B7: =SUM(Checks!G2:G417) -> 0 | C7: 0 | D7: =B7-C7 -> 0 | F7: SES-0006 | G7: =IF(COUNTIF(Script_List[Script ID],'Raw Data'!B7)=1,0,1) -> 0 | H7: =IF(COUNTIF(RawData[Session ID],F7)=1,0,1) -> 0
A8: Duplicate session IDs | B8: =SUM(Checks!H2:H417) -> 0 | C8: 0 | D8: =B8-C8 -> 0 | F8: SES-0007 | G8: =IF(COUNTIF(Script_List[Script ID],'Raw Data'!B8)=1,0,1) -> 0 | H8: =IF(COUNTIF(RawData[Session ID],F8)=1,0,1) -> 0
A9: Script/session count difference | B9: =SUM(Script_List[Observed Session Count])-COUNTA(RawData[Session ID]) -> 0 | C9: 0 | D9: =B9-C9 -> 0 | F9: SES-0008 | G9: =IF(COUNTIF(Script_List[Script ID],'Raw Data'!B9)=1,0,1) -> 0 | H9: =IF(COUNTIF(RawData[Session ID],F9)=1,0,1) -> 0
A10: Script/session contribution difference | B10: =SUM(Script_List[Cumulative Estimated Contribution])-SUM(RawData[Estimated Contribution]) -> 0 | C10: 0 | D10: =B10-C10 -> 0 | F10: SES-0009 | G10: =IF(COUNTIF(Script_List[Script ID],'Raw Data'!B10)=1,0,1) -> 0 | H10: =IF(COUNTIF(RawData[Session ID],F10)=1,0,1) -> 0
F11: SES-0010 | G11: =IF(COUNTIF(Script_List[Script ID],'Raw Data'!B11)=1,0,1) -> 0 | H11: =IF(COUNTIF(RawData[Session ID],F11)=1,0,1) -> 0
F12: SES-0011 | G12: =IF(COUNTIF(Script_List[Script ID],'Raw Data'!B12)=1,0,1) -> 0 | H12: =IF(COUNTIF(RawData[Session ID],F12)=1,0,1) -> 0
F13: SES-0012 | G13: =IF(COUNTIF(Script_List[Script ID],'Raw Data'!B13)=1,0,1) -> 0 | H13: =IF(COUNTIF(RawData[Session ID],F13)=1,0,1) -> 0
F14: SES-0013 | G14: =IF(COUNTIF(Script_List[Script ID],'Raw Data'!B14)=1,0,1) -> 0 | H14: =IF(COUNTIF(RawData[Session ID],F14)=1,0,1) -> 0
F15: SES-0014 | G15: =IF(COUNTIF(Script_List[Script ID],'Raw Data'!B15)=1,0,1) -> 0 | H15: =IF(COUNTIF(RawData[Session ID],F15)=1,0,1) -> 0
F16: SES-0015 | G16: =IF(COUNTIF(Script_List[Script ID],'Raw Data'!B16)=1,0,1) -> 0 | H16: =IF(COUNTIF(RawData[Session ID],F16)=1,0,1) -> 0
F17: SES-0016 | G17: =IF(COUNTIF(Script_List[Script ID],'Raw Data'!B17)=1,0,1) -> 0 | H17: =IF(COUNTIF(RawData[Session ID],F17)=1,0,1) -> 0
F18: SES-0017 | G18: =IF(COUNTIF(Script_List[Script ID],'Raw Data'!B18)=1,0,1) -> 0 | H18: =IF(COUNTIF(RawData[Session ID],F18)=1,0,1) -> 0
F19: SES-0018 | G19: =IF(COUNTIF(Script_List[Script ID],'Raw Data'!B19)=1,0,1) -> 0 | H19: =IF(COUNTIF(RawData[Session ID],F19)=1,0,1) -> 0
F20: SES-0019 | G20: =IF(COUNTIF(Script_List[Script ID],'Raw Data'!B20)=1,0,1) -> 0 | H20: =IF(COUNTIF(RawData[Session ID],F20)=1,0,1) -> 0
F21: SES-0020 | G21: =IF(COUNTIF(Script_List[Script ID],'Raw Data'!B21)=1,0,1) -> 0 | H21: =IF(COUNTIF(RawData[Session ID],F21)=1,0,1) -> 0
F22: SES-0021 | G22: =IF(COUNTIF(Script_List[Script ID],'Raw Data'!B22)=1,0,1) -> 0 | H22: =IF(COUNTIF(RawData[Session ID],F22)=1,0,1) -> 0
... F417: SES-0416 | G417: =IF(COUNTIF(Script_List[Script ID],'Raw Data'!B417)=1,0,1) -> 0 | H417: =IF(COUNTIF(RawData[Session ID],F417)=1,0,1) -> 0
